Workbook

Sheet Global Unit Master
A1: S.No | B1: Unit Code | C1: Unit Description | D1: Unit
A2: 1 | B2: UN001 | C2: Metre | D2: m
A3: 2 | B3: UN002 | C3: Square metre | D3: m2
A4: 3 | B4: UN003 | C4: Cubic metre | D4: m3
A5: 4 | B5: UN004 | C5: Feet | D5: ft
A6: 5 | B6: UN005 | C6: Square feet | D6: ft2
A7: 6 | B7: UN006 | C7: Cubic feet | D7: ft3
A8: 7 | B8: UN007 | C8: Number | D8: nos
A9: 8 | B9: UN008 | C9: Board | D9: board
A10: 9 | B10: UN009 | C10: Each | D10: each
A11: 10 | B11: UN010 | C11: Sheet | D11: sheet
A12: 11 | B12: UN011 | C12: Litre | D12: ltr
A13: 12 | B13: UN012 | C13: Millimetre | D13: mm
... A38: 37 | B38: UN037 | C38: Pair | D38: pair

Sheet Global Resource Category Master
A1: Sl. No. | B1: Resource Category Code | C1: Resource Category Description
A2: 1 | B2: RM001 | C2: Material
A3: 2 | B3: RM002 | C3: Labour
A4: 3 | B4: RM003 | C4: Plant
A5: 4 | B5: RM004 | C5: Machinery
A6: 5 | B6: RM005 | C6: Tools
A7: 6 | B7: RM006 | C7: Equipment
A8: 7 | B8: RM007 | C8: Sub-Contract
A9: 8 | B9: RM008 | C9: Logistics
A10: 9 | B10: RM009 | C10: Provisional Sum
A11: 10 | B11: RM010 | C11: Overhead
A12: 11 | B12: RM011 | C12: Consumables
A13: 12 | B13: RM012 | C13: Miscellaneous

Sheet Global Resource Master
A1: Sl. No. | B1: Resource Code | C1: Resource Category | D1: Resource Type | E1: Resource Sub-type | F1: Resource Description | G1: Resource Unit | H1: Resource Specification | I1: Brand | J1: Global Wastage % | K1: Global Rate
A2: 1 | B2: CIV-M-CEM-001 | C2: Material | D2: Civil | E2: Cement | F2: Cement OPC 33 Grade | G2: bag | H2: 1 bag = 3kg | J2: 0.1 | K2: 100
A3: 2 | B3: CIV-M-CEM-002 | C3: Material | D3: Civil | E3: Cement | F3: Cement OPC 43 Grade | G3: bag | H3: 1 bag = 3kg | J3: 0.1 | K3: 100
A4: 3 | B4: CIV-M-CEM-003 | C4: Material | D4: Civil | E4: Cement | F4: Cement OPC 53 Grade | G4: bag | H4: 1 bag = 3kg | J4: 0.1 | K4: 100
A5: 4 | B5: CIV-M-CEM-004 | C5: Material | D5: Civil | E5: Cement | F5: Cement PPC 33 Grade | G5: bag | H5: 1 bag = 3kg | J5: 0.1 | K5: 100
A6: 5 | B6: CIV-M-CEM-005 | C6: Material | D6: Civil | E6: Cement | F6: Cement PPC 43 Grade | G6: bag | H6: 1 bag = 3kg | J6: 0.1 | K6: 100
A7: 6 | B7: CIV-M-CEM-006 | C7: Material | D7: Civil | E7: Cement | F7: Cement PPC 53 Grade | G7: bag | H7: 1 bag = 3kg | J7: 0.1 | K7: 100
A8: 7 | B8: CIV-M-SND-001 | C8: Material | D8: Civil | E8: Sand | F8: River Sand Grade A | G8: unit | H8: 1 unit = 100 cft | J8: 0.1 | K8: 100
A9: 8 | B9: CIV-M-SND-002 | C9: Material | D9: Civil | E9: Sand | F9: River Sand Grade B | G9: unit | H9: 1 unit = 100 cft | J9: 0.1 | K9: 100
A10: 9 | B10: CIV-M-SND-003 | C10: Material | D10: Civil | E10: Sand | F10: River Sand Grade C | G10: unit | H10: 1 unit = 100 cft | J10: 0.1 | K10: 100
A11: 10 | B11: CIV-M-SND-004 | C11: Material | D11: Civil | E11: Sand | F11: M-Sand Grade A | G11: unit | H11: 1 unit = 100 cft | J11: 0.1 | K11: 100
A12: 11 | B12: CIV-M-SND-005 | C12: Material | D12: Civil | E12: Sand | F12: M-Sand Grade B | G12: unit | H12: 1 unit = 100 cft | J12: 0.1 | K12: 100
A13: 12 | B13: CIV-M-SND-006 | C13: Material | D13: Civil | E13: Sand | F13: M-Sand Grade C | G13: unit | H13: 1 unit = 100 cft | J13: 0.1 | K13: 100
... A17: 16 | B17: CIV-M-SND-010 | C17: Material | D17: Civil | E17: Sand | F17: P-Sand Grade C | G17: unit | H17: 1 unit = 100 cft | J17: 0.1 | K17: 100
A18: 17 | B18: CIV-M-WTR-001 | C18: Material | D18: Civil | E18: Water | F18: Water - Grade A | G18: ltr | J18: 0.1 | K18: 100
A19: 18 | B19: CIV-M-WTR-002 | C19: Material | D19: Civil | E19: Water | F19: Water - Grade B | G19: ltr | J19: 0.1 | K19: 100
A20: 19 | B20: CIV-M-WTR-003 | C20: Material | D20: Civil | E20: Water | F20: Water - Grade C | G20: ltr | J20: 0.1 | K20: 100
A21: 20 | B21: CIV-M-BRK-001 | C21: Material | D21: Civil | E21: Brick | F21: Brick Grade A | G21: nos | J21: 0.1 | K21: 100
A22: 21 | B22: CIV-M-BRK-002 | C22: Material | D22: Civil | E22: Brick | F22: Brick Grade B | G22: nos | J22: 0.1 | K22: 100
A23: 22 | B23: CIV-M-BRK-003 | C23: Material | D23: Civil | E23: Brick | F23: Brick Grade C | G23: nos | J23: 0.1 | K23: 100
A24: 23 | B24: CIV-M-BRK-004 | C24: Material | D24: Civil | E24: Brick | F24: Hollow Block Grade A | G24: nos | J24: 0.1 | K24: 100
A25: 24 | B25: CIV-M-BRK-005 | C25: Material | D25: Civil | E25: Brick | F25: Hollow Block Grade B | G25: nos | J25: 0.1 | K25: 100
A26: 25 | B26: CIV-M-BRK-006 | C26: Material | D26: Civil | E26: Brick | F26: Hollow Block Grade C | G26: nos | J26: 0.1 | K26: 100
A27: 26 | B27: CIV-M-BRK-007 | C27: Material | D27: Civil | E27: Brick | F27: Solid Block Grade A | G27: nos | J27: 0.1 | K27: 100
A28: 27 | B28: CIV-M-BRK-008 | C28: Material | D28: Civil | E28: Brick | F28: Solid Block Grade B | G28: nos | J28: 0.1 | K28: 100
A29: 28 | B29: CIV-M-BRK-009 | C29: Material | D29: Civil | E29: Brick | F29: Solid Block Grade C | G29: nos | J29: 0.1 | K29: 100
A30: 29 | B30: CIV-M-STL-001 | C30: Material | D30: Civil | E30: Steel | F30: Reinforcement - 6mm | G30: rod | H30: 1 rod = 11 m or 33 ft | J30: 0.1 | K30: 100
A31: 30 | B31: CIV-M-STL-002 | C31: Material | D31: Civil | E31: Steel | F31: Reinforcement - 9mm | G31: rod | H31: 1 rod = 11 m or 33 ft | J31: 0.1 | K31: 100
A32: 31 | B32: CIV-M-STL-003 | C32: Material | D32: Civil | E32: Steel | F32: Reinforcement - 12mm | G32: rod | H32: 1 rod = 11 m or 33 ft | J32: 0.1 | K32: 100
A33: 32 | B33: CIV-M-STL-004 | C33: Material | D33: Civil | E33: Steel | F33: Reinforcement - 15mm | G33: rod | H33: 1 rod = 11 m or 33 ft | J33: 0.1 | K33: 100
A34: 33 | B34: CIV-M-STL-005 | C34: Material | D34: Civil | E34: Steel | F34: Reinforcement - 18mm | G34: rod | H34: 1 rod = 11 m or 33 ft | J34: 0.1 | K34: 100
A35: 34 | B35: CIV-M-STL-006 | C35: Material | D35: Civil | E35: Steel | F35: Reinforcement - 22mm | G35: rod | H35: 1 rod = 11 m or 33 ft | J35: 0.1 | K35: 100
A36: 35 | B36: CIV-M-STL-007 | C36: Material | D36: Civil | E36: Steel | F36: Reinforcement - 25mm | G36: rod | H36: 1 rod = 11 m or 33 ft | J36: 0.1 | K36: 100
A37: 36 | B37: CIV-M-STL-008 | C37: Material | D37: Civil | E37: Steel | F37: Reinforcement - 30mm | G37: rod | H37: 1 rod = 11 m or 33 ft | J37: 0.1 | K37: 100
A38: 37 | B38: CIV-M-STL-009 | C38: Material | D38: Civil | E38: Steel | F38: Reinforcement - 40mm | G38: rod | H38: 1 rod = 11 m or 33 ft | J38: 0.1 | K38: 100
A39: 38 | B39: CIV-M-STL-010 | C39: Material | D39: Civil | E39: Steel | F39: Binding Wire | G39: kg | J39: 0.1 | K39: 100
A40: 39 | B40: ID-M-BRD-001 | C40: Material | D40: ID | E40: Boards | F40: 3mm MDF - Normal | G40: board | H40: 1220 x 2440mm | I40: Panel plus | J40: 0.1 | K40: 100
A41: 40 | B41: ID-M-BRD-002 | C41: Material | D41: ID | E41: Boards | F41: 4mm MDF - Normal | G41: board | H41: 1220 x 2440mm | I41: Panel plus | J41: 0.1 | K41: 100
A42: 41 | B42: ID-M-BRD-003 | C42: Material | D42: ID | E42: Boards | F42: 6mm MDF - Normal | G42: board | H42: 1220 x 2440mm | I42: Panel plus | J42: 0.1 | K42: 100
A43: 42 | B43: ID-M-BRD-004 | C43: Material | D43: ID | E43: Boards | F43: 9mm MDF - Normal | G43: board | H43: 1220 x 2440mm | I43: Panel plus | J43: 0.1 | K43: 100
...

Sheet Client BOQ
A1: Project - Interior Refurbishment for Medical Institute, Location A
A2: Bill of Quantities
A3: Sl. No. | B3: Description | C3: Quantity | D3: Unit | E3: Rate | F3: Amount
A4: 1 | B4: Preliminaries
A6: a | B6: Site Co-ordination | C6: 1 | D6: L/s | F6: =E6*C6 -> 0
A8: b | B8: Shop Drawings | C8: 1 | D8: L/s | F8: =E8*C8 -> 0
A10: c | B10: As-Built Drawings | C10: 1 | D10: L/s | F10: =E10*C10 -> 0
A12: d | B12: Material Submittals | C12: 1 | D12: L/s | F12: =E12*C12 -> 0
A14: e | B14: Sample Preparation | C14: 1 | D14: L/s | F14: =E14*C14 -> 0
A16: f | B16: Mock-ups | C16: 1 | D16: L/s | F16: =E16*C16 -> 0
A18: g | B18: Bonds | C18: 1 | D18: L/s | F18: =E18*C18 -> 0
A20: h | B20: Site-Office Setup | C20: 1 | D20: L/s | F20: =E20*C20 -> 0
A22: i | B22: Insurances | C22: 1 | D22: L/s | F22: =E22*C22 -> 0
B24: Page 1 - Sub-total | F24: =SUM(F4:F23) -> 0
B26: Summary
B28: 1 - Preliminaries
B30: Page 1 - subtotal | F30: =F24 -> 0
B32: 1 - Preliminaries Sub-total | F32: =SUM(F26:F31) -> 0
A34: 2 | B34: Demolition
A36: a | B36: Demolition of Blockwork | C36: 1 | D36: L/s | F36: =E36*C36 -> 0
A38: b | B38: Demolition of Gypsum Partition | C38: 1 | D38: L/s | F38: =E38*C38 -> 0
A40: c | B40: Stripping out HVAC Systems | C40: 1 | D40: L/s | F40: =E40*C40 -> 0
A42: d | B42: Removal of Fire Sprinklers | C42: 1 | D42: L/s | F42: =E42*C42 -> 0
A44: e | B44: Removal of Smoke & Fire Detectors | C44: 1 | D44: L/s | F44: =E44*C44 -> 0
A46: f | B46: Removal of Fire Hose Reel | C46: 1 | D46: L/s | F46: =E46*C46 -> 0
A48: g | B48: Removal of Fire Water Piping | C48: 1 | D48: L/s | F48: =E48*C48 -> 0
A50: h | B50: Removal of IT items | C50: 1 | D50: L/s | F50: =E50*C50 -> 0
A52: i | B52: Removal of Loose Furniture | C52: 1 | D52: L/s | F52: =E52*C52 -> 0
B54: Page 3 - Sub-total | F54: =SUM(F34:F53) -> 0
A56: 2 | B56: Demolition (Contd.)
A58: j | B58: Removal of Wall Panelling | C58: 1 | D58: L/s | F58: =E58*C58 -> 0
A60: k | B60: Removal of Custom-Joinery | C60: 1 | D60: L/s | F60: =E60*C60 -> 0
A62: l | B62: Removal of CCTV | C62: 1 | D62: L/s | F62: =E62*C62 -> 0
A64: m | B64: Removal of Flooring | C64: 1 | D64: L/s | F64: =E64*C64 -> 0
A66: n | B66: Removal of Ceiling | C66: 1 | D66: L/s | F66: =E66*C66 -> 0
A68: o | B68: Removal of Signages | C68: 1 | D68: L/s | F68: =E68*C68 -> 0
A70: p | B70: Removal of Doors | C70: 1 | D70: L/s | F70: =E70*C70 -> 0
A72: q | B72: Removal of Windows | C72: 1 | D72: L/s | F72: =E72*C72 -> 0
A74: r | B74: Demolition of Glass Partition | C74: 1 | D74: L/s | F74: =E74*C74 -> 0
B76: Page 4 - Sub-total | F76: =SUM(F56:F75) -> 0
...

Sheet QTO-Demolition
A1: Sl. No. | B1: Drawing | C1: Description | D1: Item | E1: L | F1: B | G1: H | H1: Sub-Item | I1: Nos | J1: Nos | K1: L | L1: B | M1: H | N1: T | O1: Qty | P1: Area | Q1: Volume | R1: Perimeter | S1: Surface Area | T1: Demolition of Blockwork | U1: Demolition of Gypsum Partition | V1: Stripping out HVAC Systems | W1: Removal of Fire Sprinklers | X1: Removal of Smoke & Fire Detectors | Y1: Removal of Fire Hose Reel | Z1: Removal of Fire Water Piping | AA1: Removal of IT items | AB1: Removal of Loose Furniture | AC1: Removal of Wall Panelling | AD1: Removal of Custom-Joinery | AE1: Removal of CCTV | AF1: Removal of Flooring | AG1: Removal of Ceiling | AH1: Removal of Signages | AI1: Removal of Doors | AJ1: Removal of Windows | AK1: Demolition of Glass Partition
A2: 1 | B2: Ground Floor | C2: Area 1 | D2: Blockwork - 100 | E2: 10 | F2: 10 | G2: 3 | H2: Wall | I2: 1 | J2: 1 | K2: =(E2+F2)*2 -> 40 | L2: 1 | M2: 3 | N2: 0.1 | O2: =PRODUCT(I2:N2) -> 12 | T2: =O2 -> 12
A3: 2 | B3: Ground Floor | C3: Area 1 | D3: Wall Panelling | E3: 10 | F3: 10 | G3: 3 | H3: Wall | I3: 1 | J3: 1 | K3: =(E3+F3)*2 -> 40 | L3: 1 | M3: 3 | O3: =PRODUCT(I3:N3) -> 120 | AC3: =O3 -> 120
A4: 3 | B4: Ground Floor | C4: Area 1 | D4: Blockwork - 150 | E4: 10 | F4: 10 | G4: 3 | H4: Wall | I4: 1 | J4: 1 | K4: =(E4+F4)*2 -> 40 | L4: 1 | M4: 3 | N4: 0.15 | O4: =PRODUCT(I4:N4) -> 18 | T4: =O4 -> 18
A5: 4 | B5: Ground Floor | C5: Area 1 | D5: Blockwork - 200 | E5: 10 | F5: 10 | G5: 3 | H5: Wall | I5: 1 | J5: 1 | K5: =(E5+F5)*2 -> 40 | L5: 1 | M5: 3 | N5: 0.2 | O5: =PRODUCT(I5:N5) -> 24 | T5: =O5 -> 24
A6: 5 | B6: Ground Floor | C6: Area 1 | D6: Wall Panelling | E6: 10 | F6: 10 | G6: 3 | H6: Wall | I6: 1 | J6: 1 | K6: =(E6+F6)*2 -> 40 | L6: 1 | M6: 3 | O6: =PRODUCT(I6:N6) -> 120 | AC6: =O6 -> 120
A7: 6 | B7: Ground Floor | C7: Area 1 | D7: Flooring | E7: 10 | F7: 10 | G7: 3 | H7: Flooring | I7: 1 | J7: 1 | K7: =E7 -> 10 | L7: =F7 -> 10 | O7: =PRODUCT(I7:N7) -> 100 | AF7: =O7 -> 100
A8: 7 | B8: Ground Floor | C8: Area 1 | D8: Ceiling | E8: 10 | F8: 10 | G8: 3 | H8: Ceiling | I8: 1 | J8: 1 | K8: =E8 -> 10 | L8: =F8 -> 10 | O8: =PRODUCT(I8:N8) -> 100 | AG8: =O8 -> 100
A9: 8 | B9: Ground Floor | C9: Area 2 | D9: Blockwork - 250 | E9: 10 | F9: 10 | G9: 3 | H9: Wall | I9: 1 | J9: 1 | K9: =(E9+F9)*2 -> 40 | L9: 1 | M9: 3 | N9: 0.25 | O9: =PRODUCT(I9:N9) -> 30 | T9: =O9 -> 30
A10: 9 | B10: Ground Floor | C10: Area 2 | D10: Blockwork - 300 | E10: 10 | F10: 10 | G10: 3 | H10: Wall | I10: 1 | J10: 1 | K10: =(E10+F10)*2 -> 40 | L10: 1 | M10: 3 | N10: 0.3 | O10: =PRODUCT(I10:N10) -> 36 | T10: =O10 -> 36
A11: 10 | B11: Ground Floor | C11: Area 2 | D11: Flooring | E11: 10 | F11: 10 | G11: 3 | H11: Flooring | I11: 1 | J11: 1 | K11: =E11 -> 10 | L11: =F11 -> 10 | O11: =PRODUCT(I11:N11) -> 100 | AF11: =O11 -> 100
A12: 11 | B12: Ground Floor | C12: Area 2 | D12: Ceiling | E12: 10 | F12: 10 | G12: 3 | H12: Ceiling | I12: 1 | J12: 1 | K12: =E12 -> 10 | L12: =F12 -> 10 | O12: =PRODUCT(I12:N12) -> 100 | AG12: =O12 -> 100
A13: 12 | B13: Ground Floor | C13: Area 3 | D13: Partition - 100 | E13: 10 | F13: 10 | G13: 3 | H13: Wall | I13: 1 | J13: 1 | K13: =(E13+F13)*2 -> 40 | L13: 1 | M13: 3 | N13: 0.1 | O13: =PRODUCT(I13:N13) -> 12 | U13: =O13 -> 12
A14: 13 | B14: Ground Floor | C14: Area 3 | D14: Partition - 150 | E14: 10 | F14: 10 | G14: 3 | H14: Wall | I14: 1 | J14: 1 | K14: =(E14+F14)*2 -> 40 | L14: 1 | M14: 3 | N14: 0.15 | O14: =PRODUCT(I14:N14) -> 18 | U14: =O14 -> 18
A15: 14 | B15: Ground Floor | C15: Area 3 | D15: Partition - 200 | E15: 10 | F15: 10 | G15: 3 | H15: Wall | I15: 1 | J15: 1 | K15: =(E15+F15)*2 -> 40 | L15: 1 | M15: 3 | N15: 0.2 | O15: =PRODUCT(I15:N15) -> 24 | U15: =O15 -> 24
A16: 15 | B16: Ground Floor | C16: Area 3 | D16: Partition - 250 | E16: 10 | F16: 10 | G16: 3 | H16: Wall | I16: 1 | J16: 1 | K16: =(E16+F16)*2 -> 40 | L16: 1 | M16: 3 | N16: 0.25 | O16: =PRODUCT(I16:N16) -> 30 | U16: =O16 -> 30
A17: 16 | B17: Ground Floor | C17: Area 3 | D17: Partition - 300 | E17: 10 | F17: 10 | G17: 3 | H17: Wall | I17: 1 | J17: 1 | K17: =(E17+F17)*2 -> 40 | L17: 1 | M17: 3 | N17: 0.3 | O17: =PRODUCT(I17:N17) -> 36 | U17: =O17 -> 36
A18: 17 | B18: Ground Floor | C18: Area 3 | D18: Flooring | E18: 10 | F18: 10 | G18: 3 | H18: Flooring | I18: 1 | J18: 1 | K18: =E18 -> 10 | L18: =F18 -> 10 | O18: =PRODUCT(I18:N18) -> 100 | AF18: =O18 -> 100
A19: 18 | B19: Ground Floor | C19: Area 3 | D19: Ceiling | E19: 10 | F19: 10 | G19: 3 | H19: Ceiling | I19: 1 | J19: 1 | K19: =E19 -> 10 | L19: =F19 -> 10 | O19: =PRODUCT(I19:N19) -> 100 | AG19: =O19 -> 100
A20: 19 | B20: Ground Floor | C20: Area 1 | D20: Glass Partition | E20: 10 | F20: 10 | G20: 3 | H20: Wall | I20: 1 | J20: 1 | K20: 40 | L20: 1 | M20: 3 | O20: =PRODUCT(I20:N20) -> 120 | AK20: =O20 -> 120
A21: 20 | B21: Ground Floor | C21: Area 2 | D21: Glass Partition | E21: 10 | F21: 10 | G21: 3 | H21: Wall | I21: 1 | J21: 1 | K21: 40 | L21: 1 | M21: 3 | O21: =PRODUCT(I21:N21) -> 120 | AK21: =O21 -> 120
A22: 21 | B22: Ground Floor | C22: Area 3 | D22: Glass Partition | E22: 10 | F22: 10 | G22: 3 | H22: Wall | I22: 1 | J22: 1 | K22: 40 | L22: 1 | M22: 3 | O22: =PRODUCT(I22:N22) -> 120 | AK22: =O22 -> 120
A23: 22 | B23: Ground Floor | C23: Area 1 | D23: Blockwork - 100 | H23: Door | I23: 10 | J23: -1 | K23: 1 | M23: 2 | N23: 0.1 | O23: =PRODUCT(I23:N23) -> -2 | T23: =O23 -> -2 | AC23: =O23 -> -2
A24: 23 | B24: Ground Floor | C24: Area 1 | D24: Blockwork - 150 | H24: Door | I24: 10 | J24: -1 | K24: 1 | M24: 2 | N24: 0.15 | O24: =PRODUCT(I24:N24) -> -3 | T24: =O24 -> -3
A25: 24 | B25: Ground Floor | C25: Area 1 | D25: Blockwork - 200 | H25: Door | I25: 10 | J25: -1 | K25: 1 | M25: 2 | N25: 0.2 | O25: =PRODUCT(I25:N25) -> -4 | T25: =O25 -> -4 | AC25: =O25 -> -4
A26: 25 | B26: Ground Floor | C26: Area 2 | D26: Blockwork - 250 | H26: Door | I26: 10 | J26: -1 | K26: 1 | M26: 2 | N26: 0.25 | O26: =PRODUCT(I26:N26) -> -5 | T26: =O26 -> -5
A27: 26 | B27: Ground Floor | C27: Area 2 | D27: Blockwork - 300 | H27: Door | I27: 10 | J27: -1 | K27: 1 | M27: 2 | N27: 0.3 | O27: =PRODUCT(I27:N27) -> -6 | T27: =O27 -> -6
A28: 27 | B28: Ground Floor | C28: Area 3 | D28: Partition - 100 | H28: Door | I28: 10 | J28: -1 | K28: 1 | M28: 2 | N28: 0.1 | O28: =PRODUCT(I28:N28) -> -2 | U28: =O28 -> -2
A29: 28 | B29: Ground Floor | C29: Area 3 | D29: Partition - 150 | H29: Door | I29: 10 | J29: -1 | K29: 1 | M29: 2 | N29: 0.15 | O29: =PRODUCT(I29:N29) -> -3 | U29: =O29 -> -3
A30: 29 | B30: Ground Floor | C30: Area 3 | D30: Partition - 200 | H30: Door | I30: 10 | J30: -1 | K30: 1 | M30: 2 | N30: 0.2 | O30: =PRODUCT(I30:N30) -> -4 | U30: =O30 -> -4
A31: 30 | B31: Ground Floor | C31: Area 3 | D31: Partition - 250 | H31: Door | I31: 10 | J31: -1 | K31: 1 | M31: 2 | N31: 0.25 | O31: =PRODUCT(I31:N31) -> -5 | U31: =O31 -> -5
A32: 31 | B32: Ground Floor | C32: Area 3 | D32: Partition - 300 | H32: Door | I32: 10 | J32: -1 | K32: 1 | M32: 2 | N32: 0.3 | O32: =PRODUCT(I32:N32) -> -6 | U32: =O32 -> -6
A33: 32 | B33: Ground Floor | C33: Area 1 | D33: Glass Partition | H33: Door | I33: 10 | J33: -1 | K33: 1 | M33: 2 | O33: =PRODUCT(I33:N33) -> -20 | AI33: =I33 -> 10 | AK33: =O33 -> -20
A34: 33 | B34: Ground Floor | C34: Area 2 | D34: Glass Partition | H34: Door | I34: 10 | J34: -1 | K34: 1 | M34: 2 | O34: =PRODUCT(I34:N34) -> -20 | AI34: =I34 -> 10 | AK34: =O34 -> -20
A35: 34 | B35: Ground Floor | C35: Area 3 | D35: Glass Partition | H35: Door | I35: 10 | J35: -1 | K35: 1 | M35: 2 | O35: =PRODUCT(I35:N35) -> -20 | AI35: =I35 -> 10 | AK35: =O35 -> -20
A36: 35 | B36: Ground Floor | C36: Area 1 | D36: Glass Partition | H36: Window | I36: 20 | J36: -1 | K36: 1 | M36: 1 | O36: =PRODUCT(I36:N36) -> -20 | AJ36: =I36 -> 20 | AK36: =O36 -> -20
A37: 36 | B37: Ground Floor | C37: Area 2 | D37: Glass Partition | H37: Window | I37: 20 | J37: -1 | K37: 1 | M37: 1 | O37: =PRODUCT(I37:N37) -> -20 | AJ37: =I37 -> 20 | AK37: =O37 -> -20
A38: 37 | B38: Ground Floor | C38: Area 3 | D38: Glass Partition | H38: Window | I38: 20 | J38: -1 | K38: 1 | M38: 1 | O38: =PRODUCT(I38:N38) -> -20 | AJ38: =I38 -> 20 | AK38: =O38 -> -20
A39: 38 | B39: Ground Floor | D39: HVAC | H39: HVAC | I39: 1 | J39: 1 | K39: 100 | O39: =PRODUCT(I39:N39) -> 100 | V39: =O39 -> 100
A40: 39 | B40: Ground Floor | D40: Fire Sprinklers | H40: Fire Sprinklers | I40: 1 | J40: 100 | O40: =PRODUCT(I40:N40) -> 100 | W40: =O40 -> 100
...

Sheet QTO-Structure
A1: Sl. No. | B1: Drawing | C1: Description | D1: Item | E1: L | F1: B | G1: H | H1: Sub-Item | I1: Nos | J1: Nos | K1: L | L1: B | M1: H | N1: T | O1: Qty | P1: Area | Q1: Volume | R1: Perimeter | S1: Surface Area | T1: M30 Concrete for Column | U1: M30 Concrete for beam | V1: M30 Concrete of Slabs | W1: Shuttering for Columns | X1: Shuttering for Beams | Y1: Shuttering for Slabs | Z1: Scaffolding for Columns | AA1: Scaffolding for Beams | AB1: Scaffolding for Slabs
A2: 1 | B2: Ground Floor | C2: 500x500 Column | D2: Columns | E2: 0.5 | F2: 0.5 | G2: 4 | H2: M30 | I2: 10 | J2: 10 | P2: =E2*F2 -> 0.25 | Q2: =I2*J2*E2*F2*G2 -> 100 | R2: =I2*J2*(E2*2+F2*2) -> 200 | S2: =+R2*G2 -> 800 | T2: =Q2 -> 100 | W2: =S2 -> 800 | Z2: =+S2 -> 800
A3: 2 | B3: First Floor | C3: 500x500 Column | D3: Columns | E3: 0.5 | F3: 0.5 | G3: 4 | H3: M30 | I3: 10 | J3: 10 | P3: =E3*F3 -> 0.25 | Q3: =I3*J3*E3*F3*G3 -> 100 | R3: =I3*J3*(E3*2+F3*2) -> 200 | S3: =+R3*G3 -> 800 | T3: =Q3 -> 100 | W3: =S3 -> 800 | Z3: =+S3 -> 800
A4: 3 | B4: Second Floor | C4: 500x500 Column | D4: Columns | E4: 0.5 | F4: 0.5 | G4: 4 | H4: M30 | I4: 10 | J4: 10 | P4: =E4*F4 -> 0.25 | Q4: =I4*J4*E4*F4*G4 -> 100 | R4: =I4*J4*(E4*2+F4*2) -> 200 | S4: =+R4*G4 -> 800 | T4: =Q4 -> 100 | W4: =S4 -> 800 | Z4: =+S4 -> 800
A5: 4 | B5: Basement | C5: 500x500 Column | D5: Columns | E5: 0.5 | F5: 0.5 | G5: 2 | H5: M30 | I5: 10 | J5: 10 | P5: =E5*F5 -> 0.25 | Q5: =I5*J5*E5*F5*G5 -> 50 | R5: =I5*J5*(E5*2+F5*2) -> 200 | S5: =+R5*G5 -> 400 | T5: =Q5 -> 50 | W5: =S5 -> 400 | Z5: =+S5 -> 400
A6: 5 | B6: Ground Floor | C6: 1000x500 Column | D6: Columns | E6: 1 | F6: 0.5 | G6: 4 | H6: M30 | I6: 10 | J6: 10 | P6: =E6*F6 -> 0.5 | Q6: =I6*J6*E6*F6*G6 -> 200 | R6: =I6*J6*(E6*2+F6*2) -> 300 | S6: =+R6*G6 -> 1200 | T6: =Q6 -> 200 | W6: =S6 -> 1200 | Z6: =+S6 -> 1200
A7: 6 | B7: First Floor | C7: 1000x500 Column | D7: Columns | E7: 1 | F7: 0.5 | G7: 4 | H7: M30 | I7: 10 | J7: 10 | P7: =E7*F7 -> 0.5 | Q7: =I7*J7*E7*F7*G7 -> 200 | R7: =I7*J7*(E7*2+F7*2) -> 300 | S7: =+R7*G7 -> 1200 | T7: =Q7 -> 200 | W7: =S7 -> 1200 | Z7: =+S7 -> 1200
A8: 7 | B8: Second Floor | C8: 1000x500 Column | D8: Columns | E8: 1 | F8: 0.5 | G8: 4 | H8: M30 | I8: 10 | J8: 10 | P8: =E8*F8 -> 0.5 | Q8: =I8*J8*E8*F8*G8 -> 200 | R8: =I8*J8*(E8*2+F8*2) -> 300 | S8: =+R8*G8 -> 1200 | T8: =Q8 -> 200 | W8: =S8 -> 1200 | Z8: =+S8 -> 1200
A9: 8 | B9: Basement | C9: 1000x500 Column | D9: Columns | E9: 1 | F9: 0.5 | G9: 1.5 | H9: M30 | I9: 10 | J9: 10 | P9: =E9*F9 -> 0.5 | Q9: =I9*J9*E9*F9*G9 -> 75 | R9: =I9*J9*(E9*2+F9*2) -> 300 | S9: =+R9*G9 -> 450 | T9: =Q9 -> 75 | W9: =S9 -> 450 | Z9: =+S9 -> 450
A10: 9 | B10: Ground Floor | C10: 500x500 Beam | D10: Beams | E10: 10 | F10: 0.5 | G10: 0.5 | H10: M30 | I10: 20 | J10: 1 | P10: =+F10*G10 -> 0.25 | Q10: =I10*J10*E10*F10*G10 -> 50 | R10: =I10*J10*E10*(F10+G10*2) -> 300 | S10: =+R10*G10 -> 150 | U10: =Q10 -> 50 | X10: =S10 -> 150 | AA10: =+S10 -> 150
A11: 10 | B11: First Floor | C11: 500x500 Beam | D11: Beams | E11: 10 | F11: 0.5 | G11: 0.5 | H11: M30 | I11: 20 | J11: 1 | P11: =+F11*G11 -> 0.25 | Q11: =I11*J11*E11*F11*G11 -> 50 | R11: =I11*J11*E11*(F11+G11*2) -> 300 | S11: =+R11*G11 -> 150 | U11: =Q11 -> 50 | X11: =S11 -> 150 | AA11: =+S11 -> 150
A12: 11 | B12: Second Floor | C12: 500x500 Beam | D12: Beams | E12: 10 | F12: 0.5 | G12: 0.5 | H12: M30 | I12: 20 | J12: 1 | P12: =+F12*G12 -> 0.25 | Q12: =I12*J12*E12*F12*G12 -> 50 | R12: =I12*J12*E12*(F12+G12*2) -> 300 | S12: =+R12*G12 -> 150 | U12: =Q12 -> 50 | X12: =S12 -> 150 | AA12: =+S12 -> 150
A13: 12 | B13: Basement | C13: 500x500 Beam | D13: Beams | E13: 10 | F13: 0.5 | G13: 0.5 | H13: M30 | I13: 20 | J13: 1 | P13: =+F13*G13 -> 0.25 | Q13: =I13*J13*E13*F13*G13 -> 50 | R13: =I13*J13*E13*(F13+G13*2) -> 300 | S13: =+R13*G13 -> 150 | U13: =Q13 -> 50 | X13: =S13 -> 150 | AA13: =+S13 -> 150
A14: 13 | B14: Ground Floor | C14: 1000x500 Beam | D14: Beams | E14: 10 | F14: 1 | G14: 0.5 | H14: M30 | I14: 20 | J14: 1 | P14: =+F14*G14 -> 0.5 | Q14: =I14*J14*E14*F14*G14 -> 100 | R14: =I14*J14*E14*(F14+G14*2) -> 400 | S14: =+R14*G14 -> 200 | U14: =Q14 -> 100 | X14: =S14 -> 200 | AA14: =+S14 -> 200
A15: 14 | B15: First Floor | C15: 1000x500 Beam | D15: Beams | E15: 10 | F15: 1 | G15: 0.5 | H15: M30 | I15: 20 | J15: 1 | P15: =+F15*G15 -> 0.5 | Q15: =I15*J15*E15*F15*G15 -> 100 | R15: =I15*J15*E15*(F15+G15*2) -> 400 | S15: =+R15*G15 -> 200 | U15: =Q15 -> 100 | X15: =S15 -> 200 | AA15: =+S15 -> 200
A16: 15 | B16: Second Floor | C16: 1000x500 Beam | D16: Beams | E16: 10 | F16: 1 | G16: 0.5 | H16: M30 | I16: 20 | J16: 1 | P16: =+F16*G16 -> 0.5 | Q16: =I16*J16*E16*F16*G16 -> 100 | R16: =I16*J16*E16*(F16+G16*2) -> 400 | S16: =+R16*G16 -> 200 | U16: =Q16 -> 100 | X16: =S16 -> 200 | AA16: =+S16 -> 200
A17: 16 | B17: Basement | C17: 1000x500 Beam | D17: Beams | E17: 10 | F17: 1 | G17: 0.5 | H17: M30 | I17: 20 | J17: 1 | P17: =+F17*G17 -> 0.5 | Q17: =I17*J17*E17*F17*G17 -> 100 | R17: =I17*J17*E17*(F17+G17*2) -> 400 | S17: =+R17*G17 -> 200 | U17: =Q17 -> 100 | X17: =S17 -> 200 | AA17: =+S17 -> 200
A18: 17 | B18: Ground Floor | C18: 200mm Slab | D18: Slab | E18: 20 | F18: 25 | G18: 0.2 | H18: M30 | I18: 1 | J18: 1 | P18: =E18*F18 -> 500 | Q18: =I18*J18*E18*F18*G18 -> 100 | R18: =I18*J18*(E18*2+F18*2) -> 90 | S18: =+R18*G18 -> 18 | V18: =Q18 -> 100 | Y18: =+P18 -> 500 | AB18: =+P18 -> 500
A19: 18 | B19: First Floor | C19: 200mm Slab | D19: Slab | E19: 20 | F19: 25 | G19: 0.2 | H19: M30 | I19: 1 | J19: 1 | P19: =E19*F19 -> 500 | Q19: =I19*J19*E19*F19*G19 -> 100 | R19: =I19*J19*(E19*2+F19*2) -> 90 | S19: =+R19*G19 -> 18 | V19: =Q19 -> 100 | Y19: =+P19 -> 500 | AB19: =+P19 -> 500
A20: 19 | B20: Second Floor | C20: 200mm Slab | D20: Slab | E20: 20 | F20: 25 | G20: 0.2 | H20: M30 | I20: 1 | J20: 1 | P20: =E20*F20 -> 500 | Q20: =I20*J20*E20*F20*G20 -> 100 | R20: =I20*J20*(E20*2+F20*2) -> 90 | S20: =+R20*G20 -> 18 | V20: =Q20 -> 100 | Y20: =+P20 -> 500 | AB20: =+P20 -> 500
A21: 20 | B21: Basement | C21: 200mm Slab | D21: Slab | E21: 20 | F21: 25 | G21: 0.2 | H21: M30 | I21: 1 | J21: 1 | P21: =E21*F21 -> 500 | Q21: =I21*J21*E21*F21*G21 -> 100 | R21: =I21*J21*(E21*2+F21*2) -> 90 | S21: =+R21*G21 -> 18 | V21: =Q21 -> 100 | Y21: =+P21 -> 500 | AB21: =+P21 -> 500
T25: =SUM(T2:T24) -> 1025 | U25: =SUM(U2:U24) -> 600 | V25: =SUM(V2:V24) -> 400 | W25: =SUM(W2:W24) -> 6850 | X25: =SUM(X2:X24) -> 1400 | Y25: =SUM(Y2:Y24) -> 2000 | Z25: =SUM(Z2:Z24) -> 6850 | AA25: =SUM(AA2:AA24) -> 1400 | AB25: =SUM(AB2:AB24) -> 2000
T26: cbm | U26: cbm | V26: cbm | W26: sqm | X26: sqm | Y26: sqm | Z26: sqm | AA26: sqm | AB26: sqm

Sheet QTO-Walls
A1: Sl. No. | B1: Drawing | C1: Description | D1: Item | E1: L | F1: B | G1: H | H1: Sub-Item | I1: Nos | J1: Nos | K1: L | L1: B | M1: H | N1: T | O1: Qty | P1: Area | Q1: Volume | R1: Perimeter | S1: Surface Area | T1: 100mm Gypsum Partitions | U1: 150mm Gypsum Partitions | V1: 200mm Gypsum Partitions | W1: 100mm Blockwork | X1: 200mm Blockwork | Y1: Gypsum False Ceiling
A2: 1 | B2: Ground Floor | C2: Room 1 | D2: Gypsum 100 | E2: 10 | F2: 10 | G2: 3 | H2: Walls | I2: 2 | J2: 1 | P2: =E2*F2 -> 100 | R2: =I2*J2*(E2*2+F2*2) -> 80 | S2: =+R2*G2 -> 240 | T2: =+S2 -> 240
A3: 2 | B3: First Floor | C3: Room 2 | D3: Gypsum 100 | E3: 10 | F3: 10 | G3: 3 | H3: Walls | I3: 2 | J3: 1 | P3: =E3*F3 -> 100 | R3: =I3*J3*(E3*2+F3*2) -> 80 | S3: =+R3*G3 -> 240 | T3: =+S3 -> 240
A4: 3 | B4: Second Floor | C4: Room 3 | D4: Gypsum 100 | E4: 10 | F4: 10 | G4: 3 | H4: Walls | I4: 2 | J4: 1 | P4: =E4*F4 -> 100 | R4: =I4*J4*(E4*2+F4*2) -> 80 | S4: =+R4*G4 -> 240 | T4: =+S4 -> 240
A5: 4 | B5: Ground Floor | C5: Room 1 | D5: Gypsum 150 | E5: 10 | F5: 10 | G5: 3 | H5: Walls | I5: 2 | J5: 1 | P5: =E5*F5 -> 100 | R5: =I5*J5*(E5*2+F5*2) -> 80 | S5: =+R5*G5 -> 240 | U5: =+S5 -> 240
A6: 5 | B6: First Floor | C6: Room 2 | D6: Gypsum 150 | E6: 10 | F6: 10 | G6: 3 | H6: Walls | I6: 2 | J6: 1 | P6: =E6*F6 -> 100 | R6: =I6*J6*(E6*2+F6*2) -> 80 | S6: =+R6*G6 -> 240 | U6: =+S6 -> 240
A7: 6 | B7: Second Floor | C7: Room 3 | D7: Gypsum 150 | E7: 10 | F7: 10 | G7: 3 | H7: Walls | I7: 2 | J7: 1 | P7: =E7*F7 -> 100 | R7: =I7*J7*(E7*2+F7*2) -> 80 | S7: =+R7*G7 -> 240 | U7: =+S7 -> 240
A8: 7 | B8: Ground Floor | C8: Room 1 | D8: Gypsum 200 | E8: 10 | F8: 10 | G8: 3 | H8: Walls | I8: 2 | J8: 1 | P8: =E8*F8 -> 100 | R8: =I8*J8*(E8*2+F8*2) -> 80 | S8: =+R8*G8 -> 240 | V8: =+S8 -> 240
A9: 8 | B9: First Floor | C9: Room 2 | D9: Gypsum 200 | E9: 10 | F9: 10 | G9: 3 | H9: Walls | I9: 2 | J9: 1 | P9: =E9*F9 -> 100 | R9: =I9*J9*(E9*2+F9*2) -> 80 | S9: =+R9*G9 -> 240 | V9: =+S9 -> 240
A10: 9 | B10: Second Floor | C10: Room 3 | D10: Gypsum 200 | E10: 10 | F10: 10 | G10: 3 | H10: Walls | I10: 2 | J10: 1 | P10: =E10*F10 -> 100 | R10: =I10*J10*(E10*2+F10*2) -> 80 | S10: =+R10*G10 -> 240 | V10: =+S10 -> 240
A11: 10 | B11: Ground Floor | C11: Room 1 | D11: Block 100 | E11: 10 | F11: 10 | G11: 3 | H11: Walls | I11: 4 | J11: 1 | P11: =E11*F11 -> 100 | R11: =I11*J11*(E11*2+F11*2) -> 160 | S11: =+R11*G11 -> 480 | W11: =+S11 -> 480
A12: 11 | B12: First Floor | C12: Room 2 | D12: Block 100 | E12: 10 | F12: 10 | G12: 3 | H12: Walls | I12: 4 | J12: 1 | P12: =E12*F12 -> 100 | R12: =I12*J12*(E12*2+F12*2) -> 160 | S12: =+R12*G12 -> 480 | W12: =+S12 -> 480
A13: 12 | B13: Second Floor | C13: Room 3 | D13: Block 100 | E13: 10 | F13: 10 | G13: 3 | H13: Walls | I13: 4 | J13: 1 | P13: =E13*F13 -> 100 | R13: =I13*J13*(E13*2+F13*2) -> 160 | S13: =+R13*G13 -> 480 | W13: =+S13 -> 480
A14: 13 | B14: Ground Floor | C14: Room 1 | D14: Block 200 | E14: 10 | F14: 10 | G14: 3 | H14: Walls | I14: 4 | J14: 1 | P14: =E14*F14 -> 100 | R14: =I14*J14*(E14*2+F14*2) -> 160 | S14: =+R14*G14 -> 480 | X14: =+S14 -> 480
A15: 14 | B15: First Floor | C15: Room 2 | D15: Block 200 | E15: 10 | F15: 10 | G15: 3 | H15: Walls | I15: 4 | J15: 1 | P15: =E15*F15 -> 100 | R15: =I15*J15*(E15*2+F15*2) -> 160 | S15: =+R15*G15 -> 480 | X15: =+S15 -> 480
A16: 15 | B16: Second Floor | C16: Room 3 | D16: Block 200 | E16: 10 | F16: 10 | G16: 3 | H16: Walls | I16: 4 | J16: 1 | P16: =E16*F16 -> 100 | R16: =I16*J16*(E16*2+F16*2) -> 160 | S16: =+R16*G16 -> 480 | X16: =+S16 -> 480
A17: 16 | B17: Ground Floor | C17: Room 1 | D17: Ceiling | E17: 10 | F17: 10 | G17: 3 | H17: Walls | I17: 1 | J17: 1 | P17: =E17*F17 -> 100 | R17: =I17*J17*(E17*2+F17*2) -> 40 | S17: =+R17*G17 -> 120 | Y17: =+P17 -> 100
A18: 17 | B18: First Floor | C18: Room 2 | D18: Ceiling | E18: 10 | F18: 10 | G18: 3 | H18: Walls | I18: 1 | J18: 1 | P18: =E18*F18 -> 100 | R18: =I18*J18*(E18*2+F18*2) -> 40 | S18: =+R18*G18 -> 120 | Y18: =+P18 -> 100
A19: 18 | B19: Second Floor | C19: Room 3 | D19: Ceiling | E19: 10 | F19: 10 | G19: 3 | H19: Ceiling | I19: 1 | J19: 1 | P19: =E19*F19 -> 100 | R19: =I19*J19*(E19*2+F19*2) -> 40 | S19: =+R19*G19 -> 120 | Y19: =+P19 -> 100
A20: 19 | B20: Ground Floor | C20: Room 1 | D20: Gypsum 100 | E20: 1 | G20: 2 | H20: Doors | I20: 20 | J20: -1 | P20: =+E20*G20*I20*J20 -> -40 | T20: =+P20 -> -40
A21: 20 | B21: First Floor | C21: Room 2 | D21: Gypsum 150 | E21: 1 | G21: 2 | H21: Doors | I21: 20 | J21: -1 | P21: =+E21*G21*I21*J21 -> -40 | U21: =+P21 -> -40
A22: 21 | B22: Second Floor | C22: Room 3 | D22: Gypsum 200 | E22: 1 | G22: 2 | H22: Doors | I22: 20 | J22: -1 | P22: =+E22*G22*I22*J22 -> -40 | V22: =+P22 -> -40
A23: 22 | B23: Ground Floor | C23: Room 1 | D23: Block 100 | E23: 1 | G23: 2 | H23: Doors | I23: 20 | J23: -1 | P23: =+E23*G23*I23*J23 -> -40 | W23: =+P23 -> -40
A24: 23 | B24: First Floor | C24: Room 2 | D24: Block 200 | E24: 1 | G24: 2 | H24: Doors | I24: 20 | J24: -1 | P24: =+E24*G24*I24*J24 -> -40 | X24: =+P24 -> -40
A25: 22 | B25: Ground Floor | C25: Room 1 | D25: Block 100 | E25: 1 | G25: 1 | H25: Windows | I25: 20 | J25: -1 | P25: =+E25*G25*I25*J25 -> -20 | W25: =+P25 -> -20
A26: 23 | B26: First Floor | C26: Room 2 | D26: Block 200 | E26: 1 | G26: 1 | H26: Windows | I26: 20 | J26: -1 | P26: =+E26*G26*I26*J26 -> -20 | X26: =+P26 -> -20
T30: =SUM(T2:T29) -> 680 | U30: =SUM(U2:U29) -> 680 | V30: =SUM(V2:V29) -> 680 | W30: =SUM(W2:W29) -> 1380 | X30: =SUM(X2:X29) -> 1380 | Y30: =SUM(Y2:Y29) -> 300
T31: sqm | U31: sqm | V31: sqm | W31: sqm | X31: sqm | Y31: sqm

Sheet QTO-Finishes
A1: Sl. No. | B1: Drawing | C1: Description | D1: Item | E1: L | F1: B | G1: H | H1: Sub-Item | I1: Nos | J1: Nos | K1: L | L1: B | M1: H | N1: T | O1: Qty | P1: Area | Q1: Volume | R1: Perimeter | S1: Surface Area | T1: Column Plastering | U1: Beam Plastering | V1: Ceiling Plastering | W1: Jamb finishing for Doors | X1: Jamb finishing for Windows | Y1: 600x600mm Porcelain Tile Flooring | Z1: Interior Emulsion Paint Finish | AA1: Exerior Emulsion Paint Finish | AB1: Decorative Texture Plaster Finish | AC1: Wall Panelling A | AD1: Wall Panelling B | AE1: Ceiling Panelling
A2: 1 | B2: Ground Floor | C2: 500x500 Column | D2: Columns | E2: 0.5 | F2: 0.5 | G2: 4 | H2: Column Plastering | I2: 10 | J2: 10 | P2: =E2*F2*I2*J2 -> 25 | R2: =(E2*2+F2*2)*I2*J2 -> 200 | S2: =+R2*G2 -> 800 | T2: =+S2 -> 800
A3: 2 | B3: First Floor | C3: 500x500 Column | D3: Columns | E3: 0.5 | F3: 0.5 | G3: 4 | H3: Column Plastering | I3: 10 | J3: 10 | P3: =E3*F3*I3*J3 -> 25 | R3: =(E3*2+F3*2)*I3*J3 -> 200 | S3: =+R3*G3 -> 800 | T3: =+S3 -> 800
A4: 3 | B4: Second Floor | C4: 500x500 Column | D4: Columns | E4: 0.5 | F4: 0.5 | G4: 4 | H4: Column Plastering | I4: 10 | J4: 10 | P4: =E4*F4*I4*J4 -> 25 | R4: =(E4*2+F4*2)*I4*J4 -> 200 | S4: =+R4*G4 -> 800 | T4: =+S4 -> 800
A5: 4 | B5: Ground Floor | C5: 1000x500 Column | D5: Columns | E5: 1 | F5: 0.5 | G5: 4 | H5: Column Plastering | I5: 10 | J5: 10 | P5: =E5*F5*I5*J5 -> 50 | R5: =(E5*2+F5*2)*I5*J5 -> 300 | S5: =+R5*G5 -> 1200 | T5: =+S5 -> 1200
A6: 5 | B6: First Floor | C6: 1000x500 Column | D6: Columns | E6: 1 | F6: 0.5 | G6: 4 | H6: Column Plastering | I6: 10 | J6: 10 | P6: =E6*F6*I6*J6 -> 50 | R6: =(E6*2+F6*2)*I6*J6 -> 300 | S6: =+R6*G6 -> 1200 | T6: =+S6 -> 1200
A7: 6 | B7: Second Floor | C7: 1000x500 Column | D7: Columns | E7: 1 | F7: 0.5 | G7: 4 | H7: Column Plastering | I7: 10 | J7: 10 | P7: =E7*F7*I7*J7 -> 50 | R7: =(E7*2+F7*2)*I7*J7 -> 300 | S7: =+R7*G7 -> 1200 | T7: =+S7 -> 1200
A8: 7 | B8: Ground Floor | C8: 500x500 Beam | D8: Beams | E8: 10 | F8: 0.5 | G8: 0.5 | H8: Beam Plastering | I8: 20 | J8: 1 | P8: =E8*F8*I8*J8 -> 100 | R8: =(G8*2+F8*2)*I8*J8 -> 40 | S8: =+R8*E8 -> 400 | U8: =+S8 -> 400
A9: 8 | B9: First Floor | C9: 500x500 Beam | D9: Beams | E9: 10 | F9: 0.5 | G9: 0.5 | H9: Beam Plastering | I9: 20 | J9: 1 | P9: =E9*F9*I9*J9 -> 100 | R9: =(G9*2+F9*2)*I9*J9 -> 40 | S9: =+R9*E9 -> 400 | U9: =+S9 -> 400
A10: 9 | B10: Second Floor | C10: 500x500 Beam | D10: Beams | E10: 10 | F10: 0.5 | G10: 0.5 | H10: Beam Plastering | I10: 20 | J10: 1 | P10: =E10*F10*I10*J10 -> 100 | R10: =(G10*2+F10*2)*I10*J10 -> 40 | S10: =+R10*E10 -> 400 | U10: =+S10 -> 400
A11: 10 | B11: Ground Floor | C11: 1000x500 Beam | D11: Beams | E11: 10 | F11: 1 | G11: 0.5 | H11: Beam Plastering | I11: 20 | J11: 1 | P11: =E11*F11*I11*J11 -> 200 | R11: =(G11*2+F11*2)*I11*J11 -> 60 | S11: =+R11*E11 -> 600 | U11: =+S11 -> 600
A12: 11 | B12: First Floor | C12: 1000x500 Beam | D12: Beams | E12: 10 | F12: 1 | G12: 0.5 | H12: Beam Plastering | I12: 20 | J12: 1 | P12: =E12*F12*I12*J12 -> 200 | R12: =(G12*2+F12*2)*I12*J12 -> 60 | S12: =+R12*E12 -> 600 | U12: =+S12 -> 600
A13: 12 | B13: Second Floor | C13: 1000x500 Beam | D13: Beams | E13: 10 | F13: 1 | G13: 0.5 | H13: Beam Plastering | I13: 20 | J13: 1 | P13: =E13*F13*I13*J13 -> 200 | R13: =(G13*2+F13*2)*I13*J13 -> 60 | S13: =+R13*E13 -> 600 | U13: =+S13 -> 600
A14: 13 | B14: Ground Floor | C14: 200mm Slab | D14: Slab | E14: 20 | F14: 25 | G14: 0.2 | H14: Slab Plastering | I14: 1 | J14: 1 | P14: =E14*F14*I14*J14 -> 500 | V14: =+P14 -> 500
A15: 14 | B15: First Floor | C15: 200mm Slab | D15: Slab | E15: 20 | F15: 25 | G15: 0.2 | H15: Slab Plastering | I15: 1 | J15: 1 | P15: =E15*F15*I15*J15 -> 500 | V15: =+P15 -> 500
A16: 15 | B16: Second Floor | C16: 200mm Slab | D16: Slab | E16: 20 | F16: 25 | G16: 0.2 | H16: Slab Plastering | I16: 1 | J16: 1 | P16: =E16*F16*I16*J16 -> 500 | V16: =+P16 -> 500
A17: 16 | B17: Ground Floor | C17: Room 1 | D17: Gypsum 100 | E17: 1 | F17: 0.1 | G17: 2 | H17: Doors | I17: 20 | J17: 1 | R17: =(E17+G17*2)*I17*J17 -> 100 | S17: =+R17*F17 -> 10 | W17: =+S17 -> 10
A18: 17 | B18: First Floor | C18: Room 2 | D18: Gypsum 150 | E18: 1 | F18: 0.15 | G18: 2 | H18: Doors | I18: 20 | J18: 1 | R18: =(E18+G18*2)*I18*J18 -> 100 | S18: =+R18*F18 -> 15 | W18: =+S18 -> 15
A19: 18 | B19: Second Floor | C19: Room 3 | D19: Gypsum 200 | E19: 1 | F19: 0.2 | G19: 2 | H19: Doors | I19: 20 | J19: 1 | R19: =(E19+G19*2)*I19*J19 -> 100 | S19: =+R19*F19 -> 20 | W19: =+S19 -> 20
A20: 19 | B20: Ground Floor | C20: Room 1 | D20: Block 100 | E20: 1 | F20: 0.1 | G20: 2 | H20: Doors | I20: 20 | J20: 1 | R20: =(E20+G20*2)*I20*J20 -> 100 | S20: =+R20*F20 -> 10 | W20: =+S20 -> 10
A21: 20 | B21: First Floor | C21: Room 2 | D21: Block 200 | E21: 1 | F21: 0.2 | G21: 2 | H21: Doors | I21: 20 | J21: 1 | R21: =(E21+G21*2)*I21*J21 -> 100 | S21: =+R21*F21 -> 20 | W21: =+S21 -> 20
A22: 21 | B22: Ground Floor | C22: Room 1 | D22: Block 100 | E22: 1 | F22: 0.1 | G22: 1 | H22: Windows | I22: 20 | J22: 1 | R22: =(E22+G22*2)*I22*J22 -> 60 | S22: =+R22*F22 -> 6 | X22: =+S22 -> 6
A23: 22 | B23: First Floor | C23: Room 2 | D23: Block 200 | E23: 1 | F23: 0.2 | G23: 1 | H23: Windows | I23: 20 | J23: 1 | R23: =(E23+G23*2)*I23*J23 -> 60 | S23: =+R23*F23 -> 12 | X23: =+S23 -> 12
A24: 23 | B24: Ground Floor | C24: Room 1 | D24: Tile | E24: 20 | F24: 25 | H24: Doors | I24: 1 | J24: 1 | P24: =+E24*F24*I24*J24 -> 500 | Y24: =+P24 -> 500
A25: 24 | B25: First Floor | C25: Room 2 | D25: Tile | E25: 20 | F25: 25 | H25: Doors | I25: 1 | J25: 1 | P25: =+E25*F25*I25*J25 -> 500 | Y25: =+P25 -> 500
A26: 25 | B26: Second Floor | C26: Room 3 | D26: Tile | E26: 20 | F26: 25 | H26: Doors | I26: 1 | J26: 1 | P26: =+E26*F26*I26*J26 -> 500 | Y26: =+P26 -> 500
A27: 26 | B27: Ground Floor | C27: Room 1 | D27: Gypsum 100 | E27: 10 | F27: 10 | G27: 3 | H27: Painting | I27: 2 | J27: 1 | R27: =I27*J27*(E27*2+F27*2) -> 80 | S27: =+R27*G27 -> 240 | Z27: =+S27 -> 240
A28: 27 | B28: First Floor | C28: Room 2 | D28: Gypsum 100 | E28: 10 | F28: 10 | G28: 3 | H28: Painting | I28: 2 | J28: 1 | R28: =I28*J28*(E28*2+F28*2) -> 80 | S28: =+R28*G28 -> 240 | Z28: =+S28 -> 240
A29: 28 | B29: Second Floor | C29: Room 3 | D29: Gypsum 100 | E29: 10 | F29: 10 | G29: 3 | H29: Painting | I29: 2 | J29: 1 | R29: =I29*J29*(E29*2+F29*2) -> 80 | S29: =+R29*G29 -> 240 | Z29: =+S29 -> 240
A30: 29 | B30: Ground Floor | C30: Room 1 | D30: Gypsum 150 | E30: 10 | F30: 10 | G30: 3 | H30: Painting | I30: 2 | J30: 1 | R30: =I30*J30*(E30*2+F30*2) -> 80 | S30: =+R30*G30 -> 240 | Z30: =+S30 -> 240
A31: 30 | B31: First Floor | C31: Room 2 | D31: Gypsum 150 | E31: 10 | F31: 10 | G31: 3 | H31: Painting | I31: 2 | J31: 1 | R31: =I31*J31*(E31*2+F31*2) -> 80 | S31: =+R31*G31 -> 240 | Z31: =+S31 -> 240
A32: 31 | B32: Second Floor | C32: Room 3 | D32: Gypsum 150 | E32: 10 | F32: 10 | G32: 3 | H32: Painting | I32: 2 | J32: 1 | R32: =I32*J32*(E32*2+F32*2) -> 80 | S32: =+R32*G32 -> 240 | Z32: =+S32 -> 240
A33: 32 | B33: Ground Floor | C33: Room 1 | D33: Gypsum 200 | E33: 10 | F33: 10 | G33: 3 | H33: Painting | I33: 2 | J33: 1 | R33: =I33*J33*(E33*2+F33*2) -> 80 | S33: =+R33*G33 -> 240 | Z33: =+S33 -> 240
A34: 33 | B34: First Floor | C34: Room 2 | D34: Gypsum 200 | E34: 10 | F34: 10 | G34: 3 | H34: Painting | I34: 2 | J34: 1 | R34: =I34*J34*(E34*2+F34*2) -> 80 | S34: =+R34*G34 -> 240 | Z34: =+S34 -> 240
A35: 34 | B35: Second Floor | C35: Room 3 | D35: Gypsum 200 | E35: 10 | F35: 10 | G35: 3 | H35: Painting | I35: 2 | J35: 1 | R35: =I35*J35*(E35*2+F35*2) -> 80 | S35: =+R35*G35 -> 240 | Z35: =+S35 -> 240
A36: 35 | B36: Ground Floor | C36: Room 1 | D36: Block 100 | E36: 10 | F36: 10 | G36: 3 | H36: Painting | I36: 4 | J36: 1 | P36: =+I36*J36*E36*F36 -> 400 | Z36: =+P36 -> 400 | AA36: =+Z36 -> 400
A37: 36 | B37: First Floor | C37: Room 2 | D37: Block 100 | E37: 10 | F37: 10 | G37: 3 | H37: Decorative Texture | I37: 4 | J37: 1 | P37: =+I37*J37*E37*F37 -> 400 | AB37: =+P37 -> 400
A38: 37 | B38: Second Floor | C38: Room 3 | D38: Block 100 | E38: 10 | F38: 10 | G38: 3 | H38: Painting | I38: 4 | J38: 1 | P38: =+I38*J38*E38*F38 -> 400 | Z38: =+P38 -> 400 | AA38: =+Z38 -> 400
A39: 38 | B39: Ground Floor | C39: Room 1 | D39: Block 200 | E39: 10 | F39: 10 | G39: 3 | H39: Painting | I39: 4 | J39: 1 | P39: =+I39*J39*E39*F39 -> 400 | Z39: =+P39 -> 400 | AA39: =+Z39 -> 400
A40: 39 | B40: First Floor | C40: Room 2 | D40: Block 200 | E40: 10 | F40: 10 | G40: 3 | H40: Decorative Texture | I40: 4 | J40: 1 | P40: =+I40*J40*E40*F40 -> 400 | AB40: =+P40 -> 400
...

Sheet QTO-Joineries
A1: Sl. No. | B1: Drawing | C1: Description | D1: Item | E1: L | F1: B | G1: H | H1: Sub-Item | I1: Nos | J1: Nos | K1: L | L1: B | M1: H | N1: T | O1: Qty | P1: Area | Q1: Perimeter | R1: Surface Area | S1: D1 | T1: D2 | U1: D3 | V1: D4 | W1: D5 | X1: Wardrobe A | Y1: Wardrobe B
A2: 54 | B2: Ground Floor | C2: Room 1 | D2: D1 | E2: 1 | G2: 2 | H2: Door | I2: 20 | J2: 1 | P2: =+I2*J2*E2*G2 -> 40 | S2: =+I2*J2 -> 20
A3: 55 | B3: First Floor | C3: Room 2 | D3: D2 | E3: 1 | G3: 2 | H3: Door | I3: 20 | J3: 1 | P3: =+I3*J3*E3*G3 -> 40 | T3: =+I3*J3 -> 20
A4: 56 | B4: Second Floor | C4: Room 3 | D4: D3 | E4: 1 | G4: 2 | H4: Door | I4: 5 | J4: 1 | P4: =+I4*J4*E4*G4 -> 10 | U4: =+I4*J4 -> 5
A5: 56 | B5: Second Floor | C5: Room 3 | D5: D4 | E5: 1 | G5: 2 | H5: Door | I5: 5 | J5: 1 | P5: =+I5*J5*E5*G5 -> 10 | V5: =+I5*J5 -> 5
A6: 56 | B6: Second Floor | C6: Room 3 | D6: D5 | E6: 1 | G6: 2 | H6: Door | I6: 10 | J6: 1 | P6: =+I6*J6*E6*G6 -> 20 | W6: =+I6*J6 -> 10
A7: 56 | B7: Ground Floor | C7: Room 1 | D7: Wardrobe A | E7: 2 | G7: 2 | H7: Wardrobe | I7: 5 | J7: 1 | P7: =+I7*J7*E7*G7 -> 20 | X7: =+I7*J7 -> 5
A8: 56 | B8: Ground Floor | C8: Room 1 | D8: Wardrobe B | E8: 2 | G8: 2 | H8: Wardrobe | I8: 5 | J8: 1 | P8: =+I8*J8*E8*G8 -> 20 | Y8: =+I8*J8 -> 5
A9: 56 | B9: First Floor | C9: Room 2 | D9: Wardrobe A | E9: 2 | G9: 2 | H9: Wardrobe | I9: 5 | J9: 1 | P9: =+I9*J9*E9*G9 -> 20 | X9: =+I9*J9 -> 5
A10: 56 | B10: First Floor | C10: Room 2 | D10: Wardrobe B | E10: 2 | G10: 2 | H10: Wardrobe | I10: 5 | J10: 1 | P10: =+I10*J10*E10*G10 -> 20 | Y10: =+I10*J10 -> 5
A11: 56 | B11: Second Floor | C11: Room 3 | D11: Wardrobe A | E11: 2 | G11: 2 | H11: Wardrobe | I11: 5 | J11: 1 | P11: =+I11*J11*E11*G11 -> 20 | X11: =+I11*J11 -> 5
A12: 56 | B12: Second Floor | C12: Room 3 | D12: Wardrobe B | E12: 2 | G12: 2 | H12: Wardrobe | I12: 5 | J12: 1 | P12: =+I12*J12*E12*G12 -> 20 | Y12: =+I12*J12 -> 5
S15: =SUM(S2:S14) -> 20 | T15: =SUM(T2:T14) -> 20 | U15: =SUM(U2:U14) -> 5 | V15: =SUM(V2:V14) -> 5 | W15: =SUM(W2:W14) -> 10 | X15: =SUM(X2:X14) -> 15 | Y15: =SUM(Y2:Y14) -> 15
S16: nos | T16: nos | U16: nos | V16: nos | W16: nos | X16: nos | Y16: nos

Sheet Working BOQ
A1: Project - Interior Refurbishment for Medical Institute, Location A
A2: Working - Bill of Quantities
A3: BOQ Code | B3: Sl. No. | C3: BOQ Category | D3: Work Category | E3: Sub Work Category | F3: Group 1 | G3: Group 2 | H3: Group 3 | I3: Description | J3: Client Qty | K3: Unit | L3: Our Qty | M3: Qty Diff | N3: Quote Qty | O3: Cost | P3: Cost Amount | Q3: Margin | R3: Margin Amount | S3: Rate | T3: Amount
I4: Overhead Margin % | Q4: 0.1
I5: Profit Margin % | Q5: 0.3
I6: Logistics Margin % | Q6: 0.025
I7: Contingency Margin % | Q7: 0.05
I8: Total Margin % | Q8: =SUM(Q4:Q7) -> 0.475
A11: 1 | B11: 1 | I11: Preliminaries
A12: 1a | B12: a | C12: Preliminaries | D12: Staff | I12: Site Co-ordination | J12: 1 | K12: L/s | L12: 1 | M12: =L12-J12 -> 0 | N12: =L12 -> 1 | O12: =VLOOKUP(A12,'Rate Analysis'!A:R,16,0) -> 100000 | P12: =+O12*N12 -> 100000 | Q12: =O12*$Q$8 -> 47500 | R12: =+Q12*N12 -> 47500 | S12: =O12+Q12 -> 147500 | T12: =+S12*N12 -> 147500
A13: 1b | B13: b | C13: Preliminaries | D13: Staff | I13: Shop Drawings | J13: 1 | K13: L/s | L13: 1 | M13: =L13-J13 -> 0 | N13: =L13 -> 1 | O13: =VLOOKUP(A13,'Rate Analysis'!A:R,16,0) -> 100000 | P13: =+O13*N13 -> 100000 | Q13: =O13*$Q$8 -> 47500 | R13: =+Q13*N13 -> 47500 | S13: =O13+Q13 -> 147500 | T13: =+S13*N13 -> 147500
A14: 1c | B14: c | C14: Preliminaries | D14: Staff | I14: As-Built Drawings | J14: 1 | K14: L/s | L14: 1 | M14: =L14-J14 -> 0 | N14: =L14 -> 1 | O14: =VLOOKUP(A14,'Rate Analysis'!A:R,16,0) -> 100000 | P14: =+O14*N14 -> 100000 | Q14: =O14*$Q$8 -> 47500 | R14: =+Q14*N14 -> 47500 | S14: =O14+Q14 -> 147500 | T14: =+S14*N14 -> 147500
A15: 1d | B15: d | C15: Preliminaries | D15: Staff | I15: Material Submittals | J15: 1 | K15: L/s | L15: 1 | M15: =L15-J15 -> 0 | N15: =L15 -> 1 | O15: =VLOOKUP(A15,'Rate Analysis'!A:R,16,0) -> 100000 | P15: =+O15*N15 -> 100000 | Q15: =O15*$Q$8 -> 47500 | R15: =+Q15*N15 -> 47500 | S15: =O15+Q15 -> 147500 | T15: =+S15*N15 -> 147500
A16: 1e | B16: e | C16: Preliminaries | D16: Staff | I16: Sample Preparation | J16: 1 | K16: L/s | L16: 1 | M16: =L16-J16 -> 0 | N16: =L16 -> 1 | O16: =VLOOKUP(A16,'Rate Analysis'!A:R,16,0) -> 100000 | P16: =+O16*N16 -> 100000 | Q16: =O16*$Q$8 -> 47500 | R16: =+Q16*N16 -> 47500 | S16: =O16+Q16 -> 147500 | T16: =+S16*N16 -> 147500
A17: 1f | B17: f | C17: Preliminaries | D17: Staff | I17: Mock-ups | J17: 1 | K17: L/s | L17: 1 | M17: =L17-J17 -> 0 | N17: =L17 -> 1 | O17: =VLOOKUP(A17,'Rate Analysis'!A:R,16,0) -> 100000 | P17: =+O17*N17 -> 100000 | Q17: =O17*$Q$8 -> 47500 | R17: =+Q17*N17 -> 47500 | S17: =O17+Q17 -> 147500 | T17: =+S17*N17 -> 147500
A18: 1g | B18: g | C18: Preliminaries | D18: Bank | I18: Bonds | J18: 1 | K18: L/s | L18: 1 | M18: =L18-J18 -> 0 | N18: =L18 -> 1 | O18: =VLOOKUP(A18,'Rate Analysis'!A:R,16,0) -> 100000 | P18: =+O18*N18 -> 100000 | Q18: =O18*$Q$8 -> 47500 | R18: =+Q18*N18 -> 47500 | S18: =O18+Q18 -> 147500 | T18: =+S18*N18 -> 147500
A19: 1h | B19: h | C19: Preliminaries | D19: Staff | I19: Site-Office Setup | J19: 1 | K19: L/s | L19: 1 | M19: =L19-J19 -> 0 | N19: =L19 -> 1 | O19: =VLOOKUP(A19,'Rate Analysis'!A:R,16,0) -> 100000 | P19: =+O19*N19 -> 100000 | Q19: =O19*$Q$8 -> 47500 | R19: =+Q19*N19 -> 47500 | S19: =O19+Q19 -> 147500 | T19: =+S19*N19 -> 147500
A20: 1i | B20: i | C20: Preliminaries | D20: Bank | I20: Insurances | J20: 1 | K20: L/s | L20: 1 | M20: =L20-J20 -> 0 | N20: =L20 -> 1 | O20: =VLOOKUP(A20,'Rate Analysis'!A:R,16,0) -> 100000 | P20: =+O20*N20 -> 100000 | Q20: =O20*$Q$8 -> 47500 | R20: =+Q20*N20 -> 47500 | S20: =O20+Q20 -> 147500 | T20: =+S20*N20 -> 147500
A22: 2 | B22: 2 | I22: Demolition
A23: 2a | B23: a | C23: Demolition | D23: Civil | I23: Demolition of Blockwork | J23: 1 | K23: L/s | L23: 1 | M23: =L23-J23 -> 0 | N23: =L23 -> 1 | O23: =VLOOKUP(A23,'Rate Analysis'!A:R,16,0) -> 1365 | P23: =+O23*N23 -> 1365 | Q23: =O23*$Q$8 -> 648.375 | R23: =+Q23*N23 -> 648.375 | S23: =O23+Q23 -> 2013.375 | T23: =+S23*N23 -> 2013.375
A24: 2b | B24: b | C24: Demolition | D24: ID | I24: Demolition of Gypsum Partition | J24: 1 | K24: L/s | L24: 1 | M24: =L24-J24 -> 0 | N24: =L24 -> 1 | O24: =VLOOKUP(A24,'Rate Analysis'!A:R,16,0) -> 1075 | P24: =+O24*N24 -> 1075 | Q24: =O24*$Q$8 -> 510.625 | R24: =+Q24*N24 -> 510.625 | S24: =O24+Q24 -> 1585.625 | T24: =+S24*N24 -> 1585.625
A25: 2c | B25: c | C25: Demolition | D25: MEP | I25: Stripping out HVAC Systems | J25: 1 | K25: L/s | L25: 1 | M25: =L25-J25 -> 0 | N25: =L25 -> 1 | O25: =VLOOKUP(A25,'Rate Analysis'!A:R,16,0) -> 1100 | P25: =+O25*N25 -> 1100 | Q25: =O25*$Q$8 -> 522.5 | R25: =+Q25*N25 -> 522.5 | S25: =O25+Q25 -> 1622.5 | T25: =+S25*N25 -> 1622.5
A26: 2d | B26: d | C26: Demolition | D26: MEP | I26: Removal of Fire Sprinklers | J26: 1 | K26: L/s | L26: 1 | M26: =L26-J26 -> 0 | N26: =L26 -> 1 | O26: =VLOOKUP(A26,'Rate Analysis'!A:R,16,0) -> 1390 | P26: =+O26*N26 -> 1390 | Q26: =O26*$Q$8 -> 660.25 | R26: =+Q26*N26 -> 660.25 | S26: =O26+Q26 -> 2050.25 | T26: =+S26*N26 -> 2050.25
A27: 2e | B27: e | C27: Demolition | D27: MEP | I27: Removal of Smoke & Fire Detectors | J27: 1 | K27: L/s | L27: 1 | M27: =L27-J27 -> 0 | N27: =L27 -> 1 | O27: =VLOOKUP(A27,'Rate Analysis'!A:R,16,0) -> 1390 | P27: =+O27*N27 -> 1390 | Q27: =O27*$Q$8 -> 660.25 | R27: =+Q27*N27 -> 660.25 | S27: =O27+Q27 -> 2050.25 | T27: =+S27*N27 -> 2050.25
A28: 2f | B28: f | C28: Demolition | D28: MEP | I28: Removal of Fire Hose Reel | J28: 1 | K28: L/s | L28: 1 | M28: =L28-J28 -> 0 | N28: =L28 -> 1 | O28: =VLOOKUP(A28,'Rate Analysis'!A:R,16,0) -> 1390 | P28: =+O28*N28 -> 1390 | Q28: =O28*$Q$8 -> 660.25 | R28: =+Q28*N28 -> 660.25 | S28: =O28+Q28 -> 2050.25 | T28: =+S28*N28 -> 2050.25
A29: 2g | B29: g | C29: Demolition | D29: MEP | I29: Removal of Fire Water Piping | J29: 1 | K29: L/s | L29: 1 | M29: =L29-J29 -> 0 | N29: =L29 -> 1 | O29: =VLOOKUP(A29,'Rate Analysis'!A:R,16,0) -> 1390 | P29: =+O29*N29 -> 1390 | Q29: =O29*$Q$8 -> 660.25 | R29: =+Q29*N29 -> 660.25 | S29: =O29+Q29 -> 2050.25 | T29: =+S29*N29 -> 2050.25
A30: 2h | B30: h | C30: Demolition | D30: MEP | I30: Removal of IT items | J30: 1 | K30: L/s | L30: 1 | M30: =L30-J30 -> 0 | N30: =L30 -> 1 | O30: =VLOOKUP(A30,'Rate Analysis'!A:R,16,0) -> 1075 | P30: =+O30*N30 -> 1075 | Q30: =O30*$Q$8 -> 510.625 | R30: =+Q30*N30 -> 510.625 | S30: =O30+Q30 -> 1585.625 | T30: =+S30*N30 -> 1585.625
A31: 2i | B31: i | C31: Demolition | D31: ID | I31: Removal of Loose Furniture | J31: 1 | K31: L/s | L31: 1 | M31: =L31-J31 -> 0 | N31: =L31 -> 1 | O31: =VLOOKUP(A31,'Rate Analysis'!A:R,16,0) -> 2400 | P31: =+O31*N31 -> 2400 | Q31: =O31*$Q$8 -> 1140 | R31: =+Q31*N31 -> 1140 | S31: =O31+Q31 -> 3540 | T31: =+S31*N31 -> 3540
A32: 2j | B32: j | C32: Demolition | D32: ID | I32: Removal of Wall Panelling | J32: 1 | K32: L/s | L32: 1 | M32: =L32-J32 -> 0 | N32: =L32 -> 1 | O32: =VLOOKUP(A32,'Rate Analysis'!A:R,16,0) -> 2400 | P32: =+O32*N32 -> 2400 | Q32: =O32*$Q$8 -> 1140 | R32: =+Q32*N32 -> 1140 | S32: =O32+Q32 -> 3540 | T32: =+S32*N32 -> 3540
A33: 2k | B33: k | C33: Demolition | D33: ID | I33: Removal of Custom-Joinery | J33: 1 | K33: L/s | L33: 1 | M33: =L33-J33 -> 0 | N33: =L33 -> 1 | O33: =VLOOKUP(A33,'Rate Analysis'!A:R,16,0) -> 2400 | P33: =+O33*N33 -> 2400 | Q33: =O33*$Q$8 -> 1140 | R33: =+Q33*N33 -> 1140 | S33: =O33+Q33 -> 3540 | T33: =+S33*N33 -> 3540
A34: 2l | B34: l | C34: Demolition | D34: MEP | I34: Removal of CCTV | J34: 1 | K34: L/s | L34: 1 | M34: =L34-J34 -> 0 | N34: =L34 -> 1 | O34: =VLOOKUP(A34,'Rate Analysis'!A:R,16,0) -> 1075 | P34: =+O34*N34 -> 1075 | Q34: =O34*$Q$8 -> 510.625 | R34: =+Q34*N34 -> 510.625 | S34: =O34+Q34 -> 1585.625 | T34: =+S34*N34 -> 1585.625
... A40: 2r | B40: r | C40: Demolition | D40: ID | I40: Demolition of Glass Partition | J40: 1 | K40: L/s | L40: 1 | M40: =L40-J40 -> 0 | N40: =L40 -> 1 | O40: =VLOOKUP(A40,'Rate Analysis'!A:R,16,0) -> 52.5 | P40: =+O40*N40 -> 52.5 | Q40: =O40*$Q$8 -> 24.9375 | R40: =+Q40*N40 -> 24.9375 | S40: =O40+Q40 -> 77.4375 | T40: =+S40*N40 -> 77.4375
A42: 3 | B42: 3 | I42: Civil Works
A43: 3a | B43: a | C43: Civil Works | D43: Civil | E43: Concrete | I43: M30 Concrete for Columns | J43: 1025 | K43: cbm | L43: ='QTO-Structure'!T25 -> 1025 | M43: =L43-J43 -> 0 | N43: =L43 -> 1025 | O43: =VLOOKUP(A43,'Rate Analysis'!A:R,16,0) -> 1667.5 | P43: =+O43*N43 -> 1709187.5 | Q43: =O43*$Q$8 -> 792.0625 | R43: =+Q43*N43 -> 811864.06 | S43: =O43+Q43 -> 2459.5625 | T43: =+S43*N43 -> 2521051.6
A44: 3b | B44: b | C44: Civil Works | D44: Civil | E44: Concrete | I44: M30 Concrete for Beams | J44: 100 | K44: cbm | L44: =+'QTO-Structure'!U25 -> 600 | M44: =L44-J44 -> 500 | N44: =L44 -> 600 | O44: =VLOOKUP(A44,'Rate Analysis'!A:R,16,0) -> 2375 | P44: =+O44*N44 -> 1425000 | Q44: =O44*$Q$8 -> 1128.125 | R44: =+Q44*N44 -> 676875 | S44: =O44+Q44 -> 3503.125 | T44: =+S44*N44 -> 2101875
A45: 3c | B45: c | C45: Civil Works | D45: Civil | E45: Concrete | I45: M30 Concrete for Slabs | J45: 400 | K45: cbm | L45: =+'QTO-Structure'!V25 -> 400 | M45: =L45-J45 -> 0 | N45: =L45 -> 400 | O45: =VLOOKUP(A45,'Rate Analysis'!A:R,16,0) -> 1655 | P45: =+O45*N45 -> 662000 | Q45: =O45*$Q$8 -> 786.125 | R45: =+Q45*N45 -> 314450 | S45: =O45+Q45 -> 2441.125 | T45: =+S45*N45 -> 976450
A46: 3d | B46: d | C46: Civil Works | D46: Civil | E46: Steel | I46: Pre-tensioning works | J46: 1 | K46: L/s | L46: 1 | M46: =L46-J46 -> 0 | N46: =L46 -> 1 | O46: =VLOOKUP(A46,'Rate Analysis'!A:R,16,0) -> 123500 | P46: =+O46*N46 -> 123500 | Q46: =O46*$Q$8 -> 58662.5 | R46: =+Q46*N46 -> 58662.5 | S46: =O46+Q46 -> 182162.5 | T46: =+S46*N46 -> 182162.5
A47: 3e | B47: e | C47: Civil Works | D47: Civil | E47: Shuttering | I47: Shuttering for Columns | J47: 6850 | K47: sqm | L47: =+'QTO-Structure'!W25 -> 6850 | M47: =L47-J47 -> 0 | N47: =L47 -> 6850 | O47: =VLOOKUP(A47,'Rate Analysis'!A:R,16,0) -> 150 | P47: =+O47*N47 -> 1027500 | Q47: =O47*$Q$8 -> 71.25 | R47: =+Q47*N47 -> 488062.5 | S47: =O47+Q47 -> 221.25 | T47: =+S47*N47 -> 1515562.5
A48: 3f | B48: f | C48: Civil Works | D48: Civil | E48: Shuttering | I48: Shuttering for Beams | J48: 1000 | K48: sqm | L48: =+'QTO-Structure'!X25 -> 1400 | M48: =L48-J48 -> 400 | N48: =L48 -> 1400 | O48: =VLOOKUP(A48,'Rate Analysis'!A:R,16,0) -> 180 | P48: =+O48*N48 -> 252000 | Q48: =O48*$Q$8 -> 85.5 | R48: =+Q48*N48 -> 119700 | S48: =O48+Q48 -> 265.5 | T48: =+S48*N48 -> 371700
A49: 3g | B49: g | C49: Civil Works | D49: Civil | E49: Shuttering | I49: Shuttering for Slabs | J49: 2000 | K49: sqm | L49: =+'QTO-Structure'!Y25 -> 2000 | M49: =L49-J49 -> 0 | N49: =L49 -> 2000 | O49: =VLOOKUP(A49,'Rate Analysis'!A:R,16,0) -> 190 | P49: =+O49*N49 -> 380000 | Q49: =O49*$Q$8 -> 90.25 | R49: =+Q49*N49 -> 180500 | S49: =O49+Q49 -> 280.25 | T49: =+S49*N49 -> 560500
...

Sheet Project Resource Master
A1: Sl. No. | B1: Resource Code | C1: Project Resource Code | D1: Resource Category | E1: Resource Type | F1: Resource Sub-type | G1: Resource Description | H1: Resource Unit | I1: Resource Specification | J1: Brand | K1: Global Wastage % | L1: Global Rate | M1: Project Wastage % | N1: Project Rate | O1: Total Qty | P1: Total Amount
A2: 1 | B2: CIV-M-CEM-002 | C2: PRJ-CIV-M-CEM-001 | D2: Material | E2: Civil | F2: Cement | G2: Cement OPC 43 Grade | H2: bag | I2: 1 bag = 3kg | K2: 0.1 | L2: 100 | M2: 0.1 | N2: ='Material Supplier Comparison'!L3 -> 50 | O2: =SUMIF('Rate Analysis'!B:B,C2,'Rate Analysis'!Q:Q) -> 98309.75 | P2: =N2*O2 -> 4915487.5
A3: 2 | B3: CIV-M-CEM-003 | C3: PRJ-CIV-M-CEM-002 | D3: Material | E3: Civil | F3: Cement | G3: Cement OPC 53 Grade | H3: bag | I3: 1 bag = 3kg | K3: 0.1 | L3: 100 | M3: 0.05 | N3: ='Material Supplier Comparison'!L4 -> 50 | O3: =SUMIF('Rate Analysis'!B:B,C3,'Rate Analysis'!Q:Q) -> 5250 | P3: =N3*O3 -> 262500
A4: 3 | B4: CIV-M-SND-004 | C4: PRJ-CIV-M-SND-001 | D4: Material | E4: Civil | F4: Sand | G4: M-Sand Grade A | H4: unit | I4: 1 unit = 100 cft | K4: 0.1 | L4: 100 | M4: 0.1 | N4: ='Material Supplier Comparison'!L5 -> 50 | O4: =SUMIF('Rate Analysis'!B:B,C4,'Rate Analysis'!Q:Q) -> 1567.5 | P4: =N4*O4 -> 78375
A5: 4 | B5: CIV-M-SND-005 | C5: PRJ-CIV-M-SND-002 | D5: Material | E5: Civil | F5: Sand | G5: M-Sand Grade B | H5: unit | I5: 1 unit = 100 cft | K5: 0.1 | L5: 100 | M5: 0.05 | N5: ='Material Supplier Comparison'!L6 -> 400 | O5: =SUMIF('Rate Analysis'!B:B,C5,'Rate Analysis'!Q:Q) -> 630 | P5: =N5*O5 -> 252000
A6: 5 | B6: CIV-M-SND-007 | C6: PRJ-CIV-M-SND-003 | D6: Material | E6: Civil | F6: Sand | G6: P-Sand Grade A | H6: unit | I6: 1 unit = 100 cft | K6: 0.1 | L6: 100 | M6: 0.05 | N6: ='Material Supplier Comparison'!L7 -> 50 | O6: =SUMIF('Rate Analysis'!B:B,C6,'Rate Analysis'!Q:Q) -> 19914.3 | P6: =N6*O6 -> 995715
A7: 6 | B7: CIV-M-WTR-001 | C7: PRJ-CIV-M-WTR-001 | D7: Material | E7: Civil | F7: Water | G7: Water - Grade A | H7: ltr | K7: 0.1 | L7: 100 | M7: 0.05 | N7: ='Material Supplier Comparison'!L8 -> 50 | O7: =SUMIF('Rate Analysis'!B:B,C7,'Rate Analysis'!Q:Q) -> 214105.5 | P7: =N7*O7 -> 10705275
A8: 7 | B8: CIV-M-WTR-002 | C8: PRJ-CIV-M-WTR-002 | D8: Material | E8: Civil | F8: Water | G8: Water - Grade B | H8: ltr | K8: 0.1 | L8: 100 | M8: 0.1 | N8: ='Material Supplier Comparison'!L9 -> 80 | O8: =SUMIF('Rate Analysis'!B:B,C8,'Rate Analysis'!Q:Q) -> 6600 | P8: =N8*O8 -> 528000
A9: 8 | B9: CIV-M-BRK-004 | C9: PRJ-CIV-M-BRK-001 | D9: Material | E9: Civil | F9: Brick | G9: Hollow Block Grade A | H9: nos | K9: 0.1 | L9: 100 | M9: 0.05 | N9: ='Material Supplier Comparison'!L10 -> 50 | O9: =SUMIF('Rate Analysis'!B:B,C9,'Rate Analysis'!Q:Q) -> 144900 | P9: =N9*O9 -> 7245000
A10: 9 | B10: CIV-M-BRK-007 | C10: PRJ-CIV-M-BRK-002 | D10: Material | E10: Civil | F10: Brick | G10: Solid Block Grade A | H10: nos | K10: 0.1 | L10: 100 | M10: 0.1 | N10: ='Material Supplier Comparison'!L11 -> 50 | O10: =SUMIF('Rate Analysis'!B:B,C10,'Rate Analysis'!Q:Q) -> 303600 | P10: =N10*O10 -> 15180000
A11: 10 | B11: ID-M-BRD-007 | C11: PRJ-ID-M-BRD-001 | D11: Material | E11: ID | F11: Boards | G11: 18mm MDF - Normal | H11: board | I11: 1220 x 2440mm | J11: Panel plus | K11: 0.1 | L11: 100 | M11: 0.05 | N11: ='Material Supplier Comparison'!L12 -> 50 | O11: =SUMIF('Rate Analysis'!B:B,C11,'Rate Analysis'!Q:Q) -> 1259.6354 | P11: =N11*O11 -> 62981.771
A12: 11 | B12: ID-M-BRD-015 | C12: PRJ-ID-M-BRD-003 | D12: Material | E12: ID | F12: Boards | G12: 9mm MDF - MR Grade | H12: board | I12: 1220 x 2440mm | J12: Panel plus | K12: 0.1 | L12: 100 | M12: 0.05 | N12: ='Material Supplier Comparison'!L13 -> 50 | O12: =SUMIF('Rate Analysis'!B:B,C12,'Rate Analysis'!Q:Q) -> 364.58333 | P12: =N12*O12 -> 18229.167
A13: 12 | B13: ID-M-BRD-018 | C13: PRJ-ID-M-BRD-002 | D13: Material | E13: ID | F13: Boards | G13: 18mm MDF - MR Grade | H13: board | I13: 1220 x 2440mm | J13: Panel plus | K13: 0.1 | L13: 100 | M13: 0.1 | N13: ='Material Supplier Comparison'!L14 -> 50 | O13: =SUMIF('Rate Analysis'!B:B,C13,'Rate Analysis'!Q:Q) -> 381.94444 | P13: =N13*O13 -> 19097.222
A14: 13 | B14: ID-M-WD-002 | C14: PRJ-ID-M-WD-003 | D14: Material | E14: ID | F14: Wood | G14: Meranti wood - 2" x 8" - AD | H14: cft | K14: 0.1 | L14: 100 | M14: 0.1 | N14: ='Material Supplier Comparison'!L15 -> 80 | O14: =SUMIF('Rate Analysis'!B:B,C14,'Rate Analysis'!Q:Q) -> 1049.8889 | P14: =N14*O14 -> 83991.111
A15: 14 | B15: ID-M-WD-006 | C15: PRJ-ID-M-WD-001 | D15: Material | E15: ID | F15: Wood | G15: Ash wood - 2" x 8" - AD | H15: cft | K15: 0.1 | L15: 100 | M15: 0.1 | N15: ='Material Supplier Comparison'!L16 -> 50 | O15: =SUMIF('Rate Analysis'!B:B,C15,'Rate Analysis'!Q:Q) -> 152.26215 | P15: =N15*O15 -> 7613.1076
A16: 15 | B16: ID-M-WD-042 | C16: PRJ-ID-M-WD-002 | D16: Material | E16: ID | F16: Wood | G16: Beech wood - 2" x 8" - KD | H16: cft | K16: 0.1 | L16: 100 | M16: 0.1 | N16: ='Material Supplier Comparison'!L17 -> 50 | O16: =SUMIF('Rate Analysis'!B:B,C16,'Rate Analysis'!Q:Q) -> 217.78472 | P16: =N16*O16 -> 10889.236
A17: 16 | B17: ID-M-VNR-001 | C17: PRJ-ID-M-VNR-001 | D17: Material | E17: ID | F17: Veneer | G17: Ash veneer - Q-Cut | H17: sqm | K17: 0.1 | L17: 100 | M17: 0.05 | N17: ='Material Supplier Comparison'!L18 -> 80 | O17: =SUMIF('Rate Analysis'!B:B,C17,'Rate Analysis'!Q:Q) -> 1653.75 | P17: =N17*O17 -> 132300
A18: 17 | B18: ID-M-VNR-002 | C18: PRJ-ID-M-VNR-003 | D18: Material | E18: ID | F18: Veneer | G18: Beech veneer - Q-Cut | H18: sqm | K18: 0.1 | L18: 100 | M18: 0.1 | N18: ='Material Supplier Comparison'!L19 -> 50 | O18: =SUMIF('Rate Analysis'!B:B,C18,'Rate Analysis'!Q:Q) -> 3960 | P18: =N18*O18 -> 198000
A19: 18 | B19: ID-M-VNR-019 | C19: PRJ-ID-M-VNR-002 | D19: Material | E19: ID | F19: Veneer | G19: Balancer Veneer | H19: sqm | K19: 0.1 | L19: 100 | M19: 0.05 | N19: ='Material Supplier Comparison'!L20 -> 50 | O19: =SUMIF('Rate Analysis'!B:B,C19,'Rate Analysis'!Q:Q) -> 5265.75 | P19: =N19*O19 -> 263287.5
A20: 19 | B20: ID-M-DR-001 | C20: PRJ-ID-M-DR-002 | D20: Material | E20: ID | F20: Door Core | G20: 44mm thick NON FR Hollow Door Core | H20: board | I20: 1220 x 2440mm | K20: 0.1 | L20: 100 | M20: 0.1 | N20: ='Material Supplier Comparison'!L21 -> 50 | O20: =SUMIF('Rate Analysis'!B:B,C20,'Rate Analysis'!Q:Q) -> 44 | P20: =N20*O20 -> 2200
A21: 20 | B21: ID-M-DR-002 | C21: PRJ-ID-M-DR-001 | D21: Material | E21: ID | F21: Door Core | G21: 44mm thick NON FR Solid Door Core | H21: board | I21: 915 x 2135mm | K21: 0.1 | L21: 100 | M21: 0.05 | N21: ='Material Supplier Comparison'!L22 -> 50 | O21: =SUMIF('Rate Analysis'!B:B,C21,'Rate Analysis'!Q:Q) -> 31.5 | P21: =N21*O21 -> 1575
A22: 21 | B22: ID-M-DR-009 | C22: PRJ-ID-M-DR-003 | D22: Material | E22: ID | F22: Door Core | G22: 54mm thick 60mins FR Door Core | H22: board | I22: 1220 x 2440mm | K22: 0.1 | L22: 100 | M22: 0.1 | N22: ='Material Supplier Comparison'!L23 -> 50 | O22: =SUMIF('Rate Analysis'!B:B,C22,'Rate Analysis'!Q:Q) -> 5.5 | P22: =N22*O22 -> 275
A23: 22 | B23: ID-M-DR-013 | C23: PRJ-ID-M-DR-004 | D23: Material | E23: ID | F23: Door Core | G23: 64mm thick 120mins FR Door Core | H23: board | I23: 1220 x 2440mm | K23: 0.1 | L23: 100 | M23: 0.1 | N23: ='Material Supplier Comparison'!L24 -> 50 | O23: =SUMIF('Rate Analysis'!B:B,C23,'Rate Analysis'!Q:Q) -> 11 | P23: =N23*O23 -> 550
A24: 23 | B24: CIV-L-001 | C24: PRJ-CIV-L-001 | D24: Labour | E24: Civil | G24: Stone Mason | H24: hr | K24: 0.1 | L24: 100 | M24: 0.05 | N24: ='Labour Comparison'!L3 -> 80 | O24: =SUMIF('Rate Analysis'!B:B,C24,'Rate Analysis'!Q:Q) -> 10.5 | P24: =N24*O24 -> 840
A25: 24 | B25: CIV-L-002 | C25: PRJ-CIV-L-002 | D25: Labour | E25: Civil | G25: Brick Mason | H25: hr | K25: 0.1 | L25: 100 | M25: 0.1 | N25: ='Labour Comparison'!L4 -> 50 | O25: =SUMIF('Rate Analysis'!B:B,C25,'Rate Analysis'!Q:Q) -> 22 | P25: =N25*O25 -> 1100
A26: 25 | B26: CIV-L-003 | C26: PRJ-CIV-L-003 | D26: Labour | E26: Civil | G26: Plastering Mason | H26: hr | K26: 0.1 | L26: 100 | M26: 0.05 | N26: ='Labour Comparison'!L5 -> 50 | O26: =SUMIF('Rate Analysis'!B:B,C26,'Rate Analysis'!Q:Q) -> 144018 | P26: =N26*O26 -> 7200900
